Workbook

Sheet Answers
A1: Отметка времени | B1: Recommendation ID: | C1: Source | D1: AI model | E1: Effectiveness: Considering the participant's health history and wearable device data, how effective is the recommended supplement recipe for addressing the participant's anti-aging goals? | F1: Safety: Based on the participant's health profile, does the recommendation consider and evidences possible risks, potential contraindications, interactions, or other adverse effects? | G1: Personalization: How effectively does the recommendation reflect the individual participant's specific health characteristics, lifestyle, and wearable device metrics? | H1: Overall Suitability: Considering all the above criteria collectively, how suitable is this recommendation overall for the participant? | I1: Authorship: Do you think that this recommendation was done by an AI tool or by a person? | J1: Your full name | K1: Assessor
A2: 45832.031 | B2: 1 | C2: AI | D2: Gemini 2.0 Flash | E2: 4 | F2: 3 | G2: 4 | H2: 4 | I2: 4 | J2: Hibbing Civics | K2: Assessor1
A3: 45832.756 | B3: 3 | C3: AI | D3: GPT 4o | E3: 3 | F3: 3 | G3: 2 | H3: 3 | I3: 4 | J3: Maureen trump | K3: Assessor9
A4: 45831.241 | B4: 4 | C4: Human | E4: 4 | F4: 4 | G4: 5 | H4: 4 | I4: 3 | J4: James Allen
A5: 45835.567 | B5: 5 | C5: AI | D5: Claude Opus 4 | E5: 5 | F5: 5 | G5: 4 | H5: 5 | I5: 4 | J5: Florence Davies | K5: Assessor4
A6: 45832.034 | B6: 6 | C6: Human | E6: 3 | F6: 2 | G6: 2 | H6: 3 | I6: 2 | J6: Hibbing Civics | K6: Assessor1
A7: 45837.29 | B7: 6 | C7: Human | E7: 4 | F7: 4 | G7: 4 | H7: 4 | I7: 4 | J7: Jamie Vaughn | K7: Assessor12
A8: 45832.759 | B8: 7 | C8: Human | E8: 4 | F8: 3 | G8: 4 | H8: 3 | I8: 2 | J8: Maureen trump | K8: Assessor9
A9: 45837.298 | B9: 7 | C9: Human | E9: 3 | F9: 3 | G9: 2 | H9: 4 | I9: 3 | J9: Billie Thomas | K9: Assessor11
A10: 45832.76 | B10: 8 | C10: Human | E10: 2 | F10: 2 | G10: 3 | H10: 3 | I10: 2 | J10: Maureen trump | K10: Assessor9
A11: 45832.036 | B11: 9 | C11: Human | E11: 3 | F11: 3 | G11: 4 | H11: 4 | I11: 3 | J11: Hibbing Civics | K11: Assessor1
A12: 45837.298 | B12: 9 | C12: Human | E12: 4 | F12: 3 | G12: 3 | H12: 2 | I12: 1 | J12: Billie Thomas | K12: Assessor11
A13: 45853.413 | B13: 10 | C13: Human | E13: 3 | F13: 4 | G13: 5 | H13: 4 | I13: 3 | J13: John Francis | K13: Assessor2
A14: 45835.568 | B14: 11 | C14: AI | D14: GPT 4o | E14: 5 | F14: 5 | G14: 5 | H14: 5 | I14: 5 | J14: Florence Davies | K14: Assessor4
A15: 45853.014 | B15: 11 | C15: AI | D15: GPT 4o | E15: 4 | F15: 5 | G15: 5 | H15: 5 | I15: 3 | J15: eunicejohn1269@gmail.com
A16: 45853.416 | B16: 11 | C16: AI | D16: GPT 4o | E16: 4 | F16: 4 | G16: 4 | H16: 4 | I16: 3 | J16: John Francis | K16: Assessor2
A17: 45835.568 | B17: 12 | C17: Human | E17: 4 | F17: 4 | G17: 5 | H17: 5 | I17: 4 | J17: Florence Davies | K17: Assessor4
A18: 45837.29 | B18: 12 | C18: Human | E18: 4 | F18: 4 | G18: 4 | H18: 4 | I18: 4 | J18: Jamie Vaughn | K18: Assessor12
A19: 45837.298 | B19: 12 | C19: Human | E19: 5 | F19: 3 | G19: 3 | H19: 1 | I19: 4 | J19: Billie Thomas | K19: Assessor11
A20: 45853.417 | B20: 13 | C20: Human | E20: 4 | F20: 5 | G20: 4 | H20: 4 | I20: 4 | J20: John Francis | K20: Assessor2
A21: 45832.039 | B21: 14 | C21: AI | D21: GPT 4o | E21: 4 | F21: 3 | G21: 3 | H21: 4 | I21: 4 | J21: Hibbing Civics | K21: Assessor1
A22: 45832.04 | B22: 15 | C22: AI | D22: Claude Opus 4 | E22: 5 | F22: 4 | G22: 3 | H22: 3 | I22: 4 | J22: Hibbing Civics | K22: Assessor1
A23: 45832.76 | B23: 15 | C23: AI | D23: Claude Opus 4 | E23: 4 | F23: 2 | G23: 1 | H23: 4 | I23: 5 | J23: Maureen trump | K23: Assessor9
A24: 45837.291 | B24: 15 | C24: AI | D24: Claude Opus 4 | E24: 3 | F24: 2 | G24: 4 | H24: 3 | I24: 4 | J24: Jamie Vaughn | K24: Assessor12
A25: 45832.761 | B25: 16 | C25: Human | E25: 5 | F25: 4 | G25: 4 | H25: 3 | I25: 5 | J25: Maureen trump | K25: Assessor9
A26: 45837.299 | B26: 16 | C26: Human | E26: 3 | F26: 3 | G26: 1 | H26: 4 | I26: 5 | J26: Billie Thomas | K26: Assessor11
A27: 45837.299 | B27: 16 | C27: Human | E27: 3 | F27: 3 | G27: 5 | H27: 3 | I27: 3 | J27: Billie Thomas | K27: Assessor11
A28: 45832.04 | B28: 19 | C28: Human | E28: 3 | F28: 3 | G28: 3 | H28: 2 | I28: 5 | J28: Hibbing Civics | K28: Assessor1
A29: 45853.431 | B29: 19 | C29: Human | E29: 4 | F29: 4 | G29: 3 | H29: 5 | I29: 4 | J29: Phillip joe | K29: Assessor10
A30: 45837.299 | B30: 20 | C30: AI | D30: GPT 4o | E30: 4 | F30: 4 | G30: 1 | H30: 4 | I30: 4 | J30: Billie Thomas | K30: Assessor11
A31: 45832.041 | B31: 21 | C31: AI | D31: Gemini 2.0 Flash | E31: 4 | F31: 4 | G31: 4 | H31: 4 | I31: 5 | J31: Hibbing Civics | K31: Assessor1
A32: 45832.761 | B32: 21 | C32: AI | D32: Gemini 2.0 Flash | E32: 3 | F32: 3 | G32: 2 | H32: 2 | I32: 2 | J32: Maureen trump | K32: Assessor9
A33: 45835.569 | B33: 22 | C33: Human | E33: 4 | F33: 3 | G33: 3 | H33: 3 | I33: 2 | J33: Florence Davies | K33: Assessor4
A34: 45837.291 | B34: 22 | C34: Human | E34: 4 | F34: 2 | G34: 4 | H34: 4 | I34: 4 | J34: Jamie Vaughn | K34: Assessor12
A35: 45835.57 | B35: 24 | C35: AI | D35: Claude Opus 4 | E35: 5 | F35: 4 | G35: 5 | H35: 5 | I35: 4 | J35: Florence Davies | K35: Assessor4
A36: 45853.432 | B36: 24 | C36: AI | D36: Claude Opus 4 | E36: 4 | F36: 4 | G36: 5 | H36: 5 | I36: 5 | J36: Phillip joe | K36: Assessor10
A37: 45832.042 | B37: 26 | C37: AI | D37: Gemini 2.0 Flash | E37: 4 | F37: 2 | G37: 4 | H37: 4 | I37: 4 | J37: Hibbing Civics | K37: Assessor1
A38: 45853.417 | B38: 26 | C38: AI | D38: Gemini 2.0 Flash | E38: 3 | F38: 5 | G38: 3 | H38: 3 | I38: 3 | J38: John Francis | K38: Assessor2
A39: 45837.291 | B39: 27 | C39: AI | D39: Claude Opus 4 | E39: 3 | F39: 4 | G39: 4 | H39: 5 | I39: 3 | J39: Jamie Vaughn | K39: Assessor12
A40: 45832.762 | B40: 28 | C40: AI | D40: Claude Opus 4 | E40: 4 | F40: 4 | G40: 2 | H40: 4 | I40: 3 | J40: Maureen trump | K40: Assessor9
...

Sheet Analysis
B1: AI | G1: Human
B2: All | C2: Gemini 2.0 Flash | D2: GPT 4o | E2: Claude Opus 4
A3: Effectiveness: Considering the participant's health history and wearable device data, how effective is the recommended supplement recipe for addressing the participant's anti-aging goals? | B3: =averageif(Answers!$C:$C,$B$1,Answers!E:E) -> 3.7522936 | C3: =AVERAGEIFS(Answers!$E:$E,Answers!$C:$C,$B$1,Answers!$D:$D,C$2) -> 3.5714286 | D3: =AVERAGEIFS(Answers!$E:$E,Answers!$C:$C,$B$1,Answers!$D:$D,D$2) -> 3.8648649 | E3: =AVERAGEIFS(Answers!$E:$E,Answers!$C:$C,$B$1,Answers!$D:$D,E$2) -> 3.8108108 | G3: =averageif(Answers!C:C,$G$1,Answers!E:E) -> 3.7416667
A4: Safety: Based on the participant's health profile, does the recommendation consider and evidences possible risks, potential contraindications, interactions, or other adverse effects? | B4: =averageif(Answers!$C:$C,$B$1,Answers!F:F) -> 3.4311927 | C4: =AVERAGEIFS(Answers!$F:$F,Answers!$C:$C,$B$1,Answers!$D:$D,C$2) -> 3.4857143 | D4: =AVERAGEIFS(Answers!$F:$F,Answers!$C:$C,$B$1,Answers!$D:$D,D$2) -> 3.4054054 | E4: =AVERAGEIFS(Answers!$F:$F,Answers!$C:$C,$B$1,Answers!$D:$D,E$2) -> 3.4054054 | G4: =averageif(Answers!$C:$C,$G$1,Answers!F:F) -> 3.475
A5: Personalization: How effectively does the recommendation reflect the individual participant's specific health characteristics, lifestyle, and wearable device metrics? | B5: =averageif(Answers!$C:$C,$B$1,Answers!G:G) -> 3.3486239 | C5: =AVERAGEIFS(Answers!$G:$G,Answers!$C:$C,$B$1,Answers!$D:$D,C$2) -> 3.2857143 | D5: =AVERAGEIFS(Answers!$G:$G,Answers!$C:$C,$B$1,Answers!$D:$D,D$2) -> 3.3783784 | E5: =AVERAGEIFS(Answers!$G:$G,Answers!$C:$C,$B$1,Answers!$D:$D,E$2) -> 3.3783784 | G5: =averageif(Answers!$C:$C,$G$1,Answers!G:G) -> 3.4916667
A6: Overall Suitability: Considering all the above criteria collectively, how suitable is this recommendation overall for the participant? | B6: =averageif(Answers!$C:$C,$B$1,Answers!H:H) -> 3.5321101 | C6: =AVERAGEIFS(Answers!$H:$H,Answers!$C:$C,$B$1,Answers!$D:$D,C$2) -> 3.4285714 | D6: =AVERAGEIFS(Answers!$H:$H,Answers!$C:$C,$B$1,Answers!$D:$D,D$2) -> 3.7027027 | E6: =AVERAGEIFS(Answers!$H:$H,Answers!$C:$C,$B$1,Answers!$D:$D,E$2) -> 3.4594595 | G6: =averageif(Answers!$C:$C,$G$1,Answers!H:H) -> 3.6
A7: Authorship: Do you think that this recommendation was done by an AI tool or by a person?
A8: LLMs | B8: =countifs(Answers!$C:$C,$B$1,Answers!$H:$H,"<3") -> 22 | C8: =countifs(Answers!$C:$C,$B$1,Answers!$H:$H,"<3",Answers!$D:$D,C$2) -> 7 | D8: =countifs(Answers!$C:$C,$B$1,Answers!$H:$H,"<3",Answers!$D:$D,D$2) -> 5 | E8: =countifs(Answers!$C:$C,$B$1,Answers!$H:$H,"<3",Answers!$D:$D,E$2) -> 10 | G8: =countifs(Answers!$C:$C,$G$1,Answers!H:H,"<3") -> 18
A9: Don't know | B9: =countifs(Answers!$C:$C,$B$1,Answers!$H:$H,"=3") -> 26 | C9: =countifs(Answers!$C:$C,$B$1,Answers!$H:$H,"=3",Answers!$D:$D,C$2) -> 9 | D9: =countifs(Answers!$C:$C,$B$1,Answers!$H:$H,"=3",Answers!$D:$D,D$2) -> 9 | E9: =countifs(Answers!$C:$C,$B$1,Answers!$H:$H,"=3",Answers!$D:$D,E$2) -> 8 | G9: =countifs(Answers!$C:$C,$G$1,Answers!H:H,"=3") -> 32
A10: Human | B10: =countifs(Answers!$C:$C,$B$1,Answers!$H:$H,">3") -> 61 | C10: =countifs(Answers!$C:$C,$B$1,Answers!$H:$H,">3",Answers!$D:$D,C$2) -> 19 | D10: =countifs(Answers!$C:$C,$B$1,Answers!$H:$H,">3",Answers!$D:$D,D$2) -> 23 | E10: =countifs(Answers!$C:$C,$B$1,Answers!$H:$H,">3",Answers!$D:$D,E$2) -> 19 | G10: =countifs(Answers!$C:$C,$G$1,Answers!H:H,">3") -> 70
B11: =SUM(B8:B10) -> 109 | C11: =countif(Answers!$D:$D,C$2) -> 35 | D11: =countif(Answers!$D:$D,D$2) -> 37 | E11: =countif(Answers!$D:$D,E$2) -> 37 | G11: =SUM(G8:G10) -> 120
A13: LLMs | B13: =B8/B$11 -> 0.20183486 | C13: =C8/C$11 -> 0.2 | D13: =D8/D$11 -> 0.13513514 | E13: =E8/E$11 -> 0.27027027 | G13: =G8/G$11 -> 0.15
A14: Do know | B14: =B9/B$11 -> 0.23853211 | C14: =C9/C$11 -> 0.25714286 | D14: =D9/D$11 -> 0.24324324 | E14: =E9/E$11 -> 0.21621622 | G14: =G9/G$11 -> 0.26666667
A15: Human | B15: =B10/B$11 -> 0.55963303 | C15: =C10/C$11 -> 0.54285714 | D15: =D10/D$11 -> 0.62162162 | E15: =E10/E$11 -> 0.51351351 | G15: =G10/G$11 -> 0.58333333
A17: p values of Mann Witney U test
A18: Effectiveness | B18: =IFERROR(__xludf.DUMMYFUNCTION("MANNWHITNEY(FILTER(Answers!E2:E230,Answers!C2:C230=""Human""), FILTER(Answers!E2:E230,Answers!C2:C230=""AI""),""p"")"),0.9761003727744906) -> 0.97610037 | C18: =IFERROR(__xludf.DUMMYFUNCTION("MANNWHITNEY(FILTER(Answers!$E$2:$E$230,Answers!$C$2:$C$230=""Human""), FILTER(Answers!$E$2:$E$230,Answers!$C$2:$C$230=""AI"",Answers!$D$2:$D$230=C$2),""p"")"),0.21064855842643948) -> 0.21064856 | D18: =IFERROR(__xludf.DUMMYFUNCTION("MANNWHITNEY(FILTER(Answers!$E$2:$E$230,Answers!$C$2:$C$230=""Human""), FILTER(Answers!$E$2:$E$230,Answers!$C$2:$C$230=""AI"",Answers!$D$2:$D$230=D$2),""p"")"),0.45534662360543665) -> 0.45534662 | E18: =IFERROR(__xludf.DUMMYFUNCTION("MANNWHITNEY(FILTER(Answers!$E$2:$E$230,Answers!$C$2:$C$230=""Human""), FILTER(Answers!$E$2:$E$230,Answers!$C$2:$C$230=""AI"",Answers!$D$2:$D$230=E$2),""p"")"),0.6882856246736604) -> 0.68828562
A19: Safety | B19: =IFERROR(__xludf.DUMMYFUNCTION("MANNWHITNEY(FILTER(Answers!F2:F230,Answers!C2:C230=""Human""), FILTER(Answers!F2:F230,Answers!C2:C230=""AI""),""p"")"),0.714746782907496) -> 0.71474678 | C19: =IFERROR(__xludf.DUMMYFUNCTION("MANNWHITNEY(FILTER(Answers!$F$2:$F$230,Answers!$C$2:$C$230=""Human""), FILTER(Answers!$F$2:$F$230,Answers!$C$2:$C$230=""AI"",Answers!$D$2:$D$230=C$2),""p"")"),0.9266887746201959) -> 0.92668877 | D19: =IFERROR(__xludf.DUMMYFUNCTION("MANNWHITNEY(FILTER(Answers!$F$2:$F$230,Answers!$C$2:$C$230=""Human""), FILTER(Answers!$F$2:$F$230,Answers!$C$2:$C$230=""AI"",Answers!$D$2:$D$230=D$2),""p"")"),0.8297150909507716) -> 0.82971509 | E19: =IFERROR(__xludf.DUMMYFUNCTION("MANNWHITNEY(FILTER(Answers!$F$2:$F$230,Answers!$C$2:$C$230=""Human""), FILTER(Answers!$F$2:$F$230,Answers!$C$2:$C$230=""AI"",Answers!$D$2:$D$230=E$2),""p"")"),0.650634020700634) -> 0.65063402
A20: Personalization | B20: =IFERROR(__xludf.DUMMYFUNCTION("MANNWHITNEY(FILTER(Answers!G2:G230,Answers!C2:C230=""Human""), FILTER(Answers!G2:G230,Answers!C2:C230=""AI""),""p"")"),0.3530441670276281) -> 0.35304417 | C20: =IFERROR(__xludf.DUMMYFUNCTION("MANNWHITNEY(FILTER(Answers!$G$2:$G$230,Answers!$C$2:$C$230=""Human""), FILTER(Answers!$G$2:$G$230,Answers!$C$2:$C$230=""AI"",Answers!$D$2:$D$230=C$2),""p"")"),0.32496354798277993) -> 0.32496355 | D20: =IFERROR(__xludf.DUMMYFUNCTION("MANNWHITNEY(FILTER(Answers!$G$2:$G$230,Answers!$C$2:$C$230=""Human""), FILTER(Answers!$G$2:$G$230,Answers!$C$2:$C$230=""AI"",Answers!$D$2:$D$230=D$2),""p"")"),0.6461728121288073) -> 0.64617281 | E20: =IFERROR(__xludf.DUMMYFUNCTION("MANNWHITNEY(FILTER(Answers!$G$2:$G$230,Answers!$C$2:$C$230=""Human""), FILTER(Answers!$G$2:$G$230,Answers!$C$2:$C$230=""AI"",Answers!$D$2:$D$230=E$2),""p"")"),0.6080546486191793) -> 0.60805465
A21: Overall Suitability | B21: =IFERROR(__xludf.DUMMYFUNCTION("MANNWHITNEY(FILTER(Answers!H2:H230,Answers!C2:C230=""Human""), FILTER(Answers!H2:H230,Answers!C2:C230=""AI""),""p"")"),0.6445442890922042) -> 0.64454429 | C21: =IFERROR(__xludf.DUMMYFUNCTION("MANNWHITNEY(FILTER(Answers!$H$2:$H$230,Answers!$C$2:$C$230=""Human""), FILTER(Answers!$H$2:$H$230,Answers!$C$2:$C$230=""AI"",Answers!$D$2:$D$230=C$2),""p"")"),0.36200252341084105) -> 0.36200252 | D21: =IFERROR(__xludf.DUMMYFUNCTION("MANNWHITNEY(FILTER(Answers!$H$2:$H$230,Answers!$C$2:$C$230=""Human""), FILTER(Answers!$H$2:$H$230,Answers!$C$2:$C$230=""AI"",Answers!$D$2:$D$230=D$2),""p"")"),0.6255237606082507) -> 0.62552376 | E21: =IFERROR(__xludf.DUMMYFUNCTION("MANNWHITNEY(FILTER(Answers!$H$2:$H$230,Answers!$C$2:$C$230=""Human""), FILTER(Answers!$H$2:$H$230,Answers!$C$2:$C$230=""AI"",Answers!$D$2:$D$230=E$2),""p"")"),0.5737868277756486) -> 0.57378683
A26: Effectiveness | B26: Gemini 2.0 Flash | C26: GPT 4o | D26: Claude Opus 4
A27: Gemini 2.0 Flash | B27: =IFERROR(__xludf.DUMMYFUNCTION("MANNWHITNEY(FILTER(Answers!$E$2:$E$230,Answers!$C$2:$C$230=""AI"",Answers!$D$2:$D$230=$A27), FILTER(Answers!$E$2:$E$230,Answers!$C$2:$C$230=""AI"",Answers!$D$2:$D$230=B$26),""p"")"),0.9999999989999999) -> 1 | C27: =IFERROR(__xludf.DUMMYFUNCTION("MANNWHITNEY(FILTER(Answers!$E$2:$E$230,Answers!$C$2:$C$230=""AI"",Answers!$D$2:$D$230=$A27), FILTER(Answers!$E$2:$E$230,Answers!$C$2:$C$230=""AI"",Answers!$D$2:$D$230=C$26),""p"")"),0.08784140893050973) -> 0.087841409 | D27: =IFERROR(__xludf.DUMMYFUNCTION("MANNWHITNEY(FILTER(Answers!$E$2:$E$230,Answers!$C$2:$C$230=""AI"",Answers!$D$2:$D$230=$A27), FILTER(Answers!$E$2:$E$230,Answers!$C$2:$C$230=""AI"",Answers!$D$2:$D$230=D$26),""p"")"),0.20699809451580076) -> 0.20699809
A28: GPT 4o | B28: =IFERROR(__xludf.DUMMYFUNCTION("MANNWHITNEY(FILTER(Answers!$E$2:$E$230,Answers!$C$2:$C$230=""AI"",Answers!$D$2:$D$230=$A28), FILTER(Answers!$E$2:$E$230,Answers!$C$2:$C$230=""AI"",Answers!$D$2:$D$230=B$26),""p"")"),0.08784140893050973) -> 0.087841409 | C28: =IFERROR(__xludf.DUMMYFUNCTION("MANNWHITNEY(FILTER(Answers!$E$2:$E$230,Answers!$C$2:$C$230=""AI"",Answers!$D$2:$D$230=$A28), FILTER(Answers!$E$2:$E$230,Answers!$C$2:$C$230=""AI"",Answers!$D$2:$D$230=C$26),""p"")"),0.9999999989999999) -> 1 | D28: =IFERROR(__xludf.DUMMYFUNCTION("MANNWHITNEY(FILTER(Answers!$E$2:$E$230,Answers!$C$2:$C$230=""AI"",Answers!$D$2:$D$230=$A28), FILTER(Answers!$E$2:$E$230,Answers!$C$2:$C$230=""AI"",Answers!$D$2:$D$230=D$26),""p"")"),0.8246085289654572) -> 0.82460853
A29: Claude Opus 4 | B29: =IFERROR(__xludf.DUMMYFUNCTION("MANNWHITNEY(FILTER(Answers!$E$2:$E$230,Answers!$C$2:$C$230=""AI"",Answers!$D$2:$D$230=$A29), FILTER(Answers!$E$2:$E$230,Answers!$C$2:$C$230=""AI"",Answers!$D$2:$D$230=B$26),""p"")"),0.20699809451580076) -> 0.20699809 | C29: =IFERROR(__xludf.DUMMYFUNCTION("MANNWHITNEY(FILTER(Answers!$E$2:$E$230,Answers!$C$2:$C$230=""AI"",Answers!$D$2:$D$230=$A29), FILTER(Answers!$E$2:$E$230,Answers!$C$2:$C$230=""AI"",Answers!$D$2:$D$230=C$26),""p"")"),0.8246085289654572) -> 0.82460853 | D29: =IFERROR(__xludf.DUMMYFUNCTION("MANNWHITNEY(FILTER(Answers!$E$2:$E$230,Answers!$C$2:$C$230=""AI"",Answers!$D$2:$D$230=$A29), FILTER(Answers!$E$2:$E$230,Answers!$C$2:$C$230=""AI"",Answers!$D$2:$D$230=D$26),""p"")"),0.9999999989999999) -> 1
A31: Safety | B31: Gemini 2.0 Flash | C31: GPT 4o | D31: Claude Opus 4
A32: Gemini 2.0 Flash | B32: =IFERROR(__xludf.DUMMYFUNCTION("MANNWHITNEY(FILTER(Answers!$F$2:$F$230,Answers!$C$2:$C$230=""AI"",Answers!$D$2:$D$230=$A27), FILTER(Answers!$F$2:$F$230,Answers!$C$2:$C$230=""AI"",Answers!$D$2:$D$230=B$26),""p"")"),0.9999999989999999) -> 1 | C32: =IFERROR(__xludf.DUMMYFUNCTION("MANNWHITNEY(FILTER(Answers!$F$2:$F$230,Answers!$C$2:$C$230=""AI"",Answers!$D$2:$D$230=$A27), FILTER(Answers!$F$2:$F$230,Answers!$C$2:$C$230=""AI"",Answers!$D$2:$D$230=C$26),""p"")"),0.8924539664793376) -> 0.89245397 | D32: =IFERROR(__xludf.DUMMYFUNCTION("MANNWHITNEY(FILTER(Answers!$F$2:$F$230,Answers!$C$2:$C$230=""AI"",Answers!$D$2:$D$230=$A27), FILTER(Answers!$F$2:$F$230,Answers!$C$2:$C$230=""AI"",Answers!$D$2:$D$230=D$26),""p"")"),0.7396131981419973) -> 0.7396132
A33: GPT 4o | B33: =IFERROR(__xludf.DUMMYFUNCTION("MANNWHITNEY(FILTER(Answers!$F$2:$F$230,Answers!$C$2:$C$230=""AI"",Answers!$D$2:$D$230=$A28), FILTER(Answers!$F$2:$F$230,Answers!$C$2:$C$230=""AI"",Answers!$D$2:$D$230=B$26),""p"")"),0.8924539664793376) -> 0.89245397 | C33: =IFERROR(__xludf.DUMMYFUNCTION("MANNWHITNEY(FILTER(Answers!$F$2:$F$230,Answers!$C$2:$C$230=""AI"",Answers!$D$2:$D$230=$A28), FILTER(Answers!$F$2:$F$230,Answers!$C$2:$C$230=""AI"",Answers!$D$2:$D$230=C$26),""p"")"),0.9999999989999999) -> 1 | D33: =IFERROR(__xludf.DUMMYFUNCTION("MANNWHITNEY(FILTER(Answers!$F$2:$F$230,Answers!$C$2:$C$230=""AI"",Answers!$D$2:$D$230=$A28), FILTER(Answers!$F$2:$F$230,Answers!$C$2:$C$230=""AI"",Answers!$D$2:$D$230=D$26),""p"")"),0.8925049706093509) -> 0.89250497
A34: Claude Opus 4 | B34: =IFERROR(__xludf.DUMMYFUNCTION("MANNWHITNEY(FILTER(Answers!$F$2:$F$230,Answers!$C$2:$C$230=""AI"",Answers!$D$2:$D$230=$A29), FILTER(Answers!$F$2:$F$230,Answers!$C$2:$C$230=""AI"",Answers!$D$2:$D$230=B$26),""p"")"),0.7396131981419973) -> 0.7396132 | C34: =IFERROR(__xludf.DUMMYFUNCTION("MANNWHITNEY(FILTER(Answers!$F$2:$F$230,Answers!$C$2:$C$230=""AI"",Answers!$D$2:$D$230=$A29), FILTER(Answers!$F$2:$F$230,Answers!$C$2:$C$230=""AI"",Answers!$D$2:$D$230=C$26),""p"")"),0.8925049706093509) -> 0.89250497 | D34: =IFERROR(__xludf.DUMMYFUNCTION("MANNWHITNEY(FILTER(Answers!$F$2:$F$230,Answers!$C$2:$C$230=""AI"",Answers!$D$2:$D$230=$A29), FILTER(Answers!$F$2:$F$230,Answers!$C$2:$C$230=""AI"",Answers!$D$2:$D$230=D$26),""p"")"),0.9999999989999999) -> 1
A36: Personalization | B36: Gemini 2.0 Flash | C36: GPT 4o | D36: Claude Opus 4
A37: Gemini 2.0 Flash | B37: =IFERROR(__xludf.DUMMYFUNCTION("MANNWHITNEY(FILTER(Answers!$G$2:$G$230,Answers!$C$2:$C$230=""AI"",Answers!$D$2:$D$230=$A27), FILTER(Answers!$G$2:$G$230,Answers!$C$2:$C$230=""AI"",Answers!$D$2:$D$230=B$26),""p"")"),0.9999999989999999) -> 1 | C37: =IFERROR(__xludf.DUMMYFUNCTION("MANNWHITNEY(FILTER(Answers!$G$2:$G$230,Answers!$C$2:$C$230=""AI"",Answers!$D$2:$D$230=$A27), FILTER(Answers!$G$2:$G$230,Answers!$C$2:$C$230=""AI"",Answers!$D$2:$D$230=C$26),""p"")"),0.7396131981419973) -> 0.7396132 | D37: =IFERROR(__xludf.DUMMYFUNCTION("MANNWHITNEY(FILTER(Answers!$G$2:$G$230,Answers!$C$2:$C$230=""AI"",Answers!$D$2:$D$230=$A27), FILTER(Answers!$G$2:$G$230,Answers!$C$2:$C$230=""AI"",Answers!$D$2:$D$230=D$26),""p"")"),0.7184491649504869) -> 0.71844917
A38: GPT 4o | B38: =IFERROR(__xludf.DUMMYFUNCTION("MANNWHITNEY(FILTER(Answers!$G$2:$G$230,Answers!$C$2:$C$230=""AI"",Answers!$D$2:$D$230=$A28), FILTER(Answers!$G$2:$G$230,Answers!$C$2:$C$230=""AI"",Answers!$D$2:$D$230=B$26),""p"")"),0.7396131981419973) -> 0.7396132 | C38: =IFERROR(__xludf.DUMMYFUNCTION("MANNWHITNEY(FILTER(Answers!$G$2:$G$230,Answers!$C$2:$C$230=""AI"",Answers!$D$2:$D$230=$A28), FILTER(Answers!$G$2:$G$230,Answers!$C$2:$C$230=""AI"",Answers!$D$2:$D$230=C$26),""p"")"),0.9999999989999999) -> 1 | D38: =IFERROR(__xludf.DUMMYFUNCTION("MANNWHITNEY(FILTER(Answers!$G$2:$G$230,Answers!$C$2:$C$230=""AI"",Answers!$D$2:$D$230=$A28), FILTER(Answers!$G$2:$G$230,Answers!$C$2:$C$230=""AI"",Answers!$D$2:$D$230=D$26),""p"")"),0.9827497003893657) -> 0.9827497
A39: Claude Opus 4 | B39: =IFERROR(__xludf.DUMMYFUNCTION("MANNWHITNEY(FILTER(Answers!$G$2:$G$230,Answers!$C$2:$C$230=""AI"",Answers!$D$2:$D$230=$A29), FILTER(Answers!$G$2:$G$230,Answers!$C$2:$C$230=""AI"",Answers!$D$2:$D$230=B$26),""p"")"),0.7184491649504869) -> 0.71844917 | C39: =IFERROR(__xludf.DUMMYFUNCTION("MANNWHITNEY(FILTER(Answers!$G$2:$G$230,Answers!$C$2:$C$230=""AI"",Answers!$D$2:$D$230=$A29), FILTER(Answers!$G$2:$G$230,Answers!$C$2:$C$230=""AI"",Answers!$D$2:$D$230=C$26),""p"")"),0.9827497003893657) -> 0.9827497 | D39: =IFERROR(__xludf.DUMMYFUNCTION("MANNWHITNEY(FILTER(Answers!$G$2:$G$230,Answers!$C$2:$C$230=""AI"",Answers!$D$2:$D$230=$A29), FILTER(Answers!$G$2:$G$230,Answers!$C$2:$C$230=""AI"",Answers!$D$2:$D$230=D$26),""p"")"),0.9999999989999999) -> 1
A41: Overall Suitability | B41: Gemini 2.0 Flash | C41: GPT 4o | D41: Claude Opus 4
A42: Gemini 2.0 Flash | B42: =IFERROR(__xludf.DUMMYFUNCTION("MANNWHITNEY(FILTER(Answers!$H$2:$H$230,Answers!$C$2:$C$230=""AI"",Answers!$D$2:$D$230=$A27), FILTER(Answers!$H$2:$H$230,Answers!$C$2:$C$230=""AI"",Answers!$D$2:$D$230=B$26),""p"")"),0.9999999989999999) -> 1 | C42: =IFERROR(__xludf.DUMMYFUNCTION("MANNWHITNEY(FILTER(Answers!$H$2:$H$230,Answers!$C$2:$C$230=""AI"",Answers!$D$2:$D$230=$A27), FILTER(Answers!$H$2:$H$230,Answers!$C$2:$C$230=""AI"",Answers!$D$2:$D$230=C$26),""p"")"),0.2528047447082846) -> 0.25280474 | D42: =IFERROR(__xludf.DUMMYFUNCTION("MANNWHITNEY(FILTER(Answers!$H$2:$H$230,Answers!$C$2:$C$230=""AI"",Answers!$D$2:$D$230=$A27), FILTER(Answers!$H$2:$H$230,Answers!$C$2:$C$230=""AI"",Answers!$D$2:$D$230=D$26),""p"")"),0.8436975639054338) -> 0.84369756
A43: GPT 4o | B43: =IFERROR(__xludf.DUMMYFUNCTION("MANNWHITNEY(FILTER(Answers!$H$2:$H$230,Answers!$C$2:$C$230=""AI"",Answers!$D$2:$D$230=$A28), FILTER(Answers!$H$2:$H$230,Answers!$C$2:$C$230=""AI"",Answers!$D$2:$D$230=B$26),""p"")"),0.2528047447082846) -> 0.25280474 | C43: =IFERROR(__xludf.DUMMYFUNCTION("MANNWHITNEY(FILTER(Answers!$H$2:$H$230,Answers!$C$2:$C$230=""AI"",Answers!$D$2:$D$230=$A28), FILTER(Answers!$H$2:$H$230,Answers!$C$2:$C$230=""AI"",Answers!$D$2:$D$230=C$26),""p"")"),0.9999999989999999) -> 1 | D43: =IFERROR(__xludf.DUMMYFUNCTION("MANNWHITNEY(FILTER(Answers!$H$2:$H$230,Answers!$C$2:$C$230=""AI"",Answers!$D$2:$D$230=$A28), FILTER(Answers!$H$2:$H$230,Answers!$C$2:$C$230=""AI"",Answers!$D$2:$D$230=D$26),""p"")"),0.42371067718008604) -> 0.42371068
A44: Claude Opus 4 | B44: =IFERROR(__xludf.DUMMYFUNCTION("MANNWHITNEY(FILTER(Answers!$H$2:$H$230,Answers!$C$2:$C$230=""AI"",Answers!$D$2:$D$230=$A29), FILTER(Answers!$H$2:$H$230,Answers!$C$2:$C$230=""AI"",Answers!$D$2:$D$230=B$26),""p"")"),0.8436975639054338) -> 0.84369756 | C44: =IFERROR(__xludf.DUMMYFUNCTION("MANNWHITNEY(FILTER(Answers!$H$2:$H$230,Answers!$C$2:$C$230=""AI"",Answers!$D$2:$D$230=$A29), FILTER(Answers!$H$2:$H$230,Answers!$C$2:$C$230=""AI"",Answers!$D$2:$D$230=C$26),""p"")"),0.42371067718008604) -> 0.42371068 | D44: =IFERROR(__xludf.DUMMYFUNCTION("MANNWHITNEY(FILTER(Answers!$H$2:$H$230,Answers!$C$2:$C$230=""AI"",Answers!$D$2:$D$230=$A29), FILTER(Answers!$H$2:$H$230,Answers!$C$2:$C$230=""AI"",Answers!$D$2:$D$230=D$26),""p"")"),0.9999999989999999) -> 1

Sheet TextualValueOfTests
B4: p values of Mann Witney U test
C5: Human vs. AI | D5: Human vs. Gemini 2.0 Flash | E5: Human vs. GPT 4o | F5: Human vs. Claude Opus 4
B6: Effectiveness | C6: 0.97610037 | D6: 0.21064856 | E6: 0.45534662 | F6: 0.68828562
B7: Safety | C7: 0.71474678 | D7: 0.92668877 | E7: 0.82971509 | F7: 0.65063402
B8: Personalization | C8: 0.35304417 | D8: 0.32496355 | E8: 0.64617281 | F8: 0.60805465
B9: Overall Suitability | C9: 0.64454429 | D9: 0.36200252 | E9: 0.62552376 | F9: 0.57378683
B13: Cross p values of Mann Witney U test
B14: Effectiveness | C14: Gemini 2.0 Flash | D14: GPT 4o | E14: Claude Opus 4
B15: Gemini 2.0 Flash | C15: 1 | D15: 0.087841409 | E15: 0.20699809
B16: GPT 4o | C16: 0.087841409 | D16: 1 | E16: 0.82460853
B17: Claude Opus 4 | C17: 0.20699809 | D17: 0.82460853 | E17: 1
B19: Safety | C19: Gemini 2.0 Flash | D19: GPT 4o | E19: Claude Opus 4
B20: Gemini 2.0 Flash | C20: 1 | D20: 0.89245397 | E20: 0.7396132
B21: GPT 4o | C21: 0.89245397 | D21: 1 | E21: 0.89250497
B22: Claude Opus 4 | C22: 0.7396132 | D22: 0.89250497 | E22: 1
B24: Personalization | C24: Gemini 2.0 Flash | D24: GPT 4o | E24: Claude Opus 4
B25: Gemini 2.0 Flash | C25: 1 | D25: 0.7396132 | E25: 0.71844916
B26: GPT 4o | C26: 0.7396132 | D26: 1 | E26: 0.9827497
B27: Claude Opus 4 | C27: 0.71844916 | D27: 0.9827497 | E27: 1
B29: Overall Suitability | C29: Gemini 2.0 Flash | D29: GPT 4o | E29: Claude Opus 4
B30: Gemini 2.0 Flash | C30: 1 | D30: 0.25280474 | E30: 0.84369756
B31: GPT 4o | C31: 0.25280474 | D31: 1 | E31: 0.42371068
B32: Claude Opus 4 | C32: 0.84369756 | D32: 0.42371068 | E32: 1
